<robot name="picar_robot">
	<link name="body_link" />
	<link name="imu_link" />
	<link name="tilt_link" />
	<link name="pan_link" />
	<link name="cam_link" />
	
	<joint name="pan_joint" type="continuous">
		<parent link="body_link"/>
		<child link="pan_link"/>
		<origin xyz="0 0.1016 0" rpy="0 0 0"/>
		<axis xyz="0 0 1"/>
	</joint>
	
	<joint name="tilt_joint" type="continuous">
		<parent link="pan_link"/>
		<child link="tilt_link"/>
		<origin xyz="0.022225 -0.00635 0.0381 " rpy="-1.57 0 0"/>
		<axis xyz="0 0 1"/>
	</joint>
	
	<joint name="cam_joint" type="continuous">
		<parent link="tilt_link" />
		<child link="cam_link"/>
		<origin xyz="0 0 0" rpy="0 0 0"/>
		<axis xyz="0 0 0"/>
	</joint>
	
	<joint name="imu_joint" type="continuous">
		<parent link="body_link" />
		<child link="imu_link"/>
		<origin xyz="-0.0127 0 0.0254" rpy="3.14 0 0"/>
		<axis xyz="0 0 0"/>
	</joint>

</robot>	

	
